[16:06:43] INFO | mcp-server | 
[16:06:43] INFO | mcp-server | 
[16:06:44] INFO | mcp-server | 
[16:07:17] INFO | mcp-server | [APP] Session session_20060dc123a1431f8132323d99c45b02: completed prompt processing
[16:29:09] INFO | mcp-server | 
[16:29:09] INFO | mcp-server | 
[16:29:09] ERROR | mcp-server | [CASEBOOK] Casebook request failed for INN 2312016641
Traceback (most recent call last):
  File "/home/user/dev/mcp-server/app/services/http_client.py", line 161, in fetch_all_pages
    response = await self._retry_request(
               ^^^^^^^^^^^^^^^^^^^^^^^^^^
  File "/home/user/dev/mcp-server/app/services/http_client.py", line 108, in _retry_request
    response.raise_for_status()
  File "/home/user/dev/mcp-server/.venv/lib/python3.12/site-packages/httpx/_models.py", line 829, in raise_for_status
    raise HTTPStatusError(message, request=request, response=self)
httpx.HTTPStatusError: Redirect response '301 Moved Permanently' for url 'http://api3.casebook.ru//arbitrage/cases?sideInn=2312016641&size=100&apikey=EoyZJiqeW3DXm0ZBHoaoz2ZCW6s52nBy&page=1'
Redirect location: 'https://api3.casebook.ru//arbitrage/cases?sideInn=2312016641&size=100&apikey=EoyZJiqeW3DXm0ZBHoaoz2ZCW6s52nBy&page=1'
For more information check: https://developer.mozilla.org/en-US/docs/Web/HTTP/Status/301

During handling of the above exception, another exception occurred:

Traceback (most recent call last):
  File "/home/user/dev/mcp-server/app/services/fetch_data.py", line 82, in fetch_from_casebook
    all_cases = await client.fetch_all_pages(url, params=params)
                ^^^^^^^^^^^^^^^^^^^^^^^^^^^^^^^^^^^^^^^^^^^^^^^^
  File "/home/user/dev/mcp-server/app/services/http_client.py", line 183, in fetch_all_pages
    logger.error("Ошибка при запросе страницы %d: %s", current_page, str(e))
  File "/home/user/dev/mcp-server/app/advanced/logging_client.py", line 149, in error
    app_logger.error(f"[{component.upper()}] {message}", exc_info=exc_info)
                         ^^^^^^^^^^^^^^^
AttributeError: 'int' object has no attribute 'upper'
[16:35:06] INFO | mcp-server | 
[16:35:06] INFO | mcp-server | 
[16:35:06] ERROR | mcp-server | [HTTP_CLIENT] Ошибка при запросе страницы 1: Redirect response '301 Moved Permanently' for url 'http://api3.casebook.ru/arbitrage/cases?sideInn=2312016641&size=100&apikey=EoyZJiqeW3DXm0ZBHoaoz2ZCW6s52nBy&page=1'
Redirect location: 'https://api3.casebook.ru/arbitrage/cases?sideInn=2312016641&size=100&apikey=EoyZJiqeW3DXm0ZBHoaoz2ZCW6s52nBy&page=1'
For more information check: https://developer.mozilla.org/en-US/docs/Web/HTTP/Status/301
[17:13:44] ERROR | mcp-server | [TARANTOOL] Tarantool connection failed: connect() got an unexpected keyword argument 'socket_timeout'
[17:14:16] INFO | mcp-server | [TARANTOOL] Tarantool connected successfully
[17:14:20] DEBUG | mcp-server | [CACHE] Cache MISS: app.services.fetch_data:fetch_from_casebook:2312016641 → cache:6d10c38a3d0ddfe170820e256d2775fc
[17:14:20] INFO | mcp-server | 
[17:14:21] INFO | mcp-server | 
[17:14:21] ERROR | mcp-server | [HTTP_CLIENT] Ошибка при запросе страницы 1: 'int' object has no attribute 'upper'
[17:14:21] DEBUG | mcp-server | [TARANTOOL] Cache set: cache:6d10c38a3d0ddfe170820e256d2775fc, ttl=9600
[17:14:21] DEBUG | mcp-server | [CACHE] Cache SET: cache:6d10c38a3d0ddfe170820e256d2775fc, ttl=9600
[17:14:44] DEBUG | mcp-server | [CACHE] Cache HIT: app.services.fetch_data:fetch_from_casebook:2312016641 → cache:6d10c38a3d0ddfe170820e256d2775fc
[17:14:47] DEBUG | mcp-server | [CACHE] Cache HIT: app.services.fetch_data:fetch_from_casebook:2312016641 → cache:6d10c38a3d0ddfe170820e256d2775fc
[17:14:52] DEBUG | mcp-server | [CACHE] Cache HIT: app.services.fetch_data:fetch_from_casebook:2312016641 → cache:6d10c38a3d0ddfe170820e256d2775fc
[17:33:48] WARNING | mcp-server | [TARANTOOL] invalidate_all_keys() called without confirm=True. Aborted.
[17:33:55] INFO | mcp-server | [TARANTOOL] Tarantool connection closed
[17:36:29] INFO | mcp-server | [TARANTOOL] Tarantool connected successfully
[17:37:14] INFO | mcp-server | [COMPANY_INFO] Fetching data for INN: 6165231522
[17:37:14] DEBUG | mcp-server | [CACHE] Cache MISS: app.services.fetch_data:fetch_from_dadata:6165231522 → cache:18ff4cb6c031705995c5866e42ff0fb9
[17:37:14] INFO | mcp-server | 
[17:37:14] DEBUG | mcp-server | [CACHE] Cache MISS: app.services.fetch_data:fetch_from_infosphere:6165231522 → cache:3c5353609bd74cf49101cf9ff5d2460b
[17:37:14] INFO | mcp-server | 
[17:37:14] DEBUG | mcp-server | [CACHE] Cache MISS: app.services.fetch_data:fetch_from_casebook:6165231522 → cache:b35111377fd6f940ce1cb56b9fcbc3f5
[17:37:14] INFO | mcp-server | 
[17:37:14] INFO | mcp-server | 
[17:37:14] DEBUG | mcp-server | [TARANTOOL] Cache set: cache:18ff4cb6c031705995c5866e42ff0fb9, ttl=7200
[17:37:14] DEBUG | mcp-server | [CACHE] Cache SET: cache:18ff4cb6c031705995c5866e42ff0fb9, ttl=7200
[17:37:14] INFO | mcp-server | 
[17:37:14] ERROR | mcp-server | [HTTP_CLIENT] Ошибка при запросе страницы 1: 'int' object has no attribute 'upper'
[17:37:14] DEBUG | mcp-server | [TARANTOOL] Cache set: cache:b35111377fd6f940ce1cb56b9fcbc3f5, ttl=9600
[17:37:14] DEBUG | mcp-server | [CACHE] Cache SET: cache:b35111377fd6f940ce1cb56b9fcbc3f5, ttl=9600
[17:37:44] ERROR | mcp-server | [INFOSPHERE] InfoSphere request failed for INN 6165231522
Traceback (most recent call last):
  File "/home/user/dev/mcp-server/.venv/lib/python3.12/site-packages/httpx/_transports/default.py", line 101, in map_httpcore_exceptions
    yield
  File "/home/user/dev/mcp-server/.venv/lib/python3.12/site-packages/httpx/_transports/default.py", line 394, in handle_async_request
    resp = await self._pool.handle_async_request(req)
           ^^^^^^^^^^^^^^^^^^^^^^^^^^^^^^^^^^^^^^^^^^
  File "/home/user/dev/mcp-server/.venv/lib/python3.12/site-packages/httpcore/_async/connection_pool.py", line 256, in handle_async_request
    raise exc from None
  File "/home/user/dev/mcp-server/.venv/lib/python3.12/site-packages/httpcore/_async/connection_pool.py", line 236, in handle_async_request
    response = await connection.handle_async_request(
               ^^^^^^^^^^^^^^^^^^^^^^^^^^^^^^^^^^^^^^
  File "/home/user/dev/mcp-server/.venv/lib/python3.12/site-packages/httpcore/_async/connection.py", line 103, in handle_async_request
    return await self._connection.handle_async_request(request)
           ^^^^^^^^^^^^^^^^^^^^^^^^^^^^^^^^^^^^^^^^^^^^^^^^^^^^
  File "/home/user/dev/mcp-server/.venv/lib/python3.12/site-packages/httpcore/_async/http11.py", line 136, in handle_async_request
    raise exc
  File "/home/user/dev/mcp-server/.venv/lib/python3.12/site-packages/httpcore/_async/http11.py", line 106, in handle_async_request
    ) = await self._receive_response_headers(**kwargs)
        ^^^^^^^^^^^^^^^^^^^^^^^^^^^^^^^^^^^^^^^^^^^^^^
  File "/home/user/dev/mcp-server/.venv/lib/python3.12/site-packages/httpcore/_async/http11.py", line 177, in _receive_response_headers
    event = await self._receive_event(timeout=timeout)
            ^^^^^^^^^^^^^^^^^^^^^^^^^^^^^^^^^^^^^^^^^^
  File "/home/user/dev/mcp-server/.venv/lib/python3.12/site-packages/httpcore/_async/http11.py", line 217, in _receive_event
    data = await self._network_stream.read(
           ^^^^^^^^^^^^^^^^^^^^^^^^^^^^^^^^
  File "/home/user/dev/mcp-server/.venv/lib/python3.12/site-packages/httpcore/_backends/anyio.py", line 32, in read
    with map_exceptions(exc_map):
  File "/usr/lib/python3.12/contextlib.py", line 158, in __exit__
    self.gen.throw(value)
  File "/home/user/dev/mcp-server/.venv/lib/python3.12/site-packages/httpcore/_exceptions.py", line 14, in map_exceptions
    raise to_exc(exc) from exc
httpcore.ReadTimeout

The above exception was the direct cause of the following exception:

Traceback (most recent call last):
  File "/home/user/dev/mcp-server/app/services/http_client.py", line 94, in _retry_request
    response = await client.request(method, url, **kwargs)
               ^^^^^^^^^^^^^^^^^^^^^^^^^^^^^^^^^^^^^^^^^^^
  File "/home/user/dev/mcp-server/.venv/lib/python3.12/site-packages/httpx/_client.py", line 1540, in request
    return await self.send(request, auth=auth, follow_redirects=follow_redirects)
           ^^^^^^^^^^^^^^^^^^^^^^^^^^^^^^^^^^^^^^^^^^^^^^^^^^^^^^^^^^^^^^^^^^^^^^
  File "/home/user/dev/mcp-server/.venv/lib/python3.12/site-packages/httpx/_client.py", line 1629, in send
    response = await self._send_handling_auth(
               ^^^^^^^^^^^^^^^^^^^^^^^^^^^^^^^
  File "/home/user/dev/mcp-server/.venv/lib/python3.12/site-packages/httpx/_client.py", line 1657, in _send_handling_auth
    response = await self._send_handling_redirects(
               ^^^^^^^^^^^^^^^^^^^^^^^^^^^^^^^^^^^^
  File "/home/user/dev/mcp-server/.venv/lib/python3.12/site-packages/httpx/_client.py", line 1694, in _send_handling_redirects
    response = await self._send_single_request(request)
               ^^^^^^^^^^^^^^^^^^^^^^^^^^^^^^^^^^^^^^^^
  File "/home/user/dev/mcp-server/.venv/lib/python3.12/site-packages/httpx/_client.py", line 1730, in _send_single_request
    response = await transport.handle_async_request(request)
               ^^^^^^^^^^^^^^^^^^^^^^^^^^^^^^^^^^^^^^^^^^^^^
  File "/home/user/dev/mcp-server/.venv/lib/python3.12/site-packages/httpx/_transports/default.py", line 393, in handle_async_request
    with map_httpcore_exceptions():
  File "/usr/lib/python3.12/contextlib.py", line 158, in __exit__
    self.gen.throw(value)
  File "/home/user/dev/mcp-server/.venv/lib/python3.12/site-packages/httpx/_transports/default.py", line 118, in map_httpcore_exceptions
    raise mapped_exc(message) from exc
httpx.ReadTimeout

During handling of the above exception, another exception occurred:

Traceback (most recent call last):
  File "/home/user/dev/mcp-server/app/services/fetch_data.py", line 60, in fetch_from_infosphere
    resp = await client.request(
           ^^^^^^^^^^^^^^^^^^^^^
  File "/home/user/dev/mcp-server/app/services/http_client.py", line 194, in request
    return await self._retry_request(method=method, url=url, **kwargs)
           ^^^^^^^^^^^^^^^^^^^^^^^^^^^^^^^^^^^^^^^^^^^^^^^^^^^^^^^^^^^
  File "/home/user/dev/mcp-server/app/services/http_client.py", line 115, in _retry_request
    logger.warning("Request error: %s. Retrying in %.2f seconds...", str(exc), delay)
TypeError: AppLogger.warning() takes from 2 to 3 positional arguments but 4 were given
[17:37:44] DEBUG | mcp-server | [CACHE] Skip caching error response: {'error': 'InfoSphere request failed: AppLogger.warning() takes from 2 to 3 positional arguments but 4 were given'}
[17:37:48] INFO | mcp-server | [APP] Session session_6f6bee5937b3424eaedcccadb11a1f67: completed prompt processing
[17:38:16] INFO | mcp-server | [COMPANY_INFO] Fetching data for INN: 6165231522
[17:38:16] ERROR | mcp-server | [TARANTOOL] Unexpected error on GET cache:18ff4cb6c031705995c5866e42ff0fb9: unpack(b) received extra data.
[17:38:16] ERROR | mcp-server | [TARANTOOL] Unexpected error on GET cache:18ff4cb6c031705995c5866e42ff0fb9: unpack(b) received extra data.
[17:38:16] ERROR | mcp-server | [TARANTOOL] Unexpected error on GET cache:18ff4cb6c031705995c5866e42ff0fb9: unpack(b) received extra data.
[17:38:16] ERROR | mcp-server | [TARANTOOL] Unexpected error on GET cache:3c5353609bd74cf49101cf9ff5d2460b: 'int' object has no attribute 'get'
[17:38:16] ERROR | mcp-server | [TARANTOOL] Unexpected error on GET cache:3c5353609bd74cf49101cf9ff5d2460b: 'int' object has no attribute 'get'
[17:38:16] ERROR | mcp-server | [TARANTOOL] Unexpected error on GET cache:b35111377fd6f940ce1cb56b9fcbc3f5: 3 exceeds max_map_len(2)
[17:38:16] ERROR | mcp-server | [TARANTOOL] Unexpected error on GET cache:3c5353609bd74cf49101cf9ff5d2460b: 'int' object has no attribute 'get'
[17:38:16] ERROR | mcp-server | [TARANTOOL] Unexpected error on GET cache:b35111377fd6f940ce1cb56b9fcbc3f5: 3 exceeds max_map_len(2)
[17:38:16] DEBUG | mcp-server | [CACHE] Cache MISS: app.services.fetch_data:fetch_from_dadata:6165231522 → cache:18ff4cb6c031705995c5866e42ff0fb9
[17:38:16] INFO | mcp-server | 
[17:38:16] DEBUG | mcp-server | [CACHE] Cache MISS: app.services.fetch_data:fetch_from_infosphere:6165231522 → cache:3c5353609bd74cf49101cf9ff5d2460b
[17:38:16] INFO | mcp-server | 
[17:38:16] DEBUG | mcp-server | [CACHE] Cache MISS: app.services.fetch_data:fetch_from_casebook:6165231522 → cache:b35111377fd6f940ce1cb56b9fcbc3f5
[17:38:16] INFO | mcp-server | 
[17:38:16] INFO | mcp-server | 
[17:38:16] ERROR | mcp-server | [HTTP_CLIENT] Ошибка при запросе страницы 1: 'int' object has no attribute 'upper'
[17:38:16] DEBUG | mcp-server | [TARANTOOL] Cache set: cache:b35111377fd6f940ce1cb56b9fcbc3f5, ttl=9600
[17:38:16] DEBUG | mcp-server | [CACHE] Cache SET: cache:b35111377fd6f940ce1cb56b9fcbc3f5, ttl=9600
[17:38:16] INFO | mcp-server | 
[17:38:16] DEBUG | mcp-server | [TARANTOOL] Cache set: cache:18ff4cb6c031705995c5866e42ff0fb9, ttl=7200
[17:38:16] DEBUG | mcp-server | [CACHE] Cache SET: cache:18ff4cb6c031705995c5866e42ff0fb9, ttl=7200
[17:38:46] ERROR | mcp-server | [INFOSPHERE] InfoSphere request failed for INN 6165231522
Traceback (most recent call last):
  File "/home/user/dev/mcp-server/.venv/lib/python3.12/site-packages/httpx/_transports/default.py", line 101, in map_httpcore_exceptions
    yield
  File "/home/user/dev/mcp-server/.venv/lib/python3.12/site-packages/httpx/_transports/default.py", line 394, in handle_async_request
    resp = await self._pool.handle_async_request(req)
           ^^^^^^^^^^^^^^^^^^^^^^^^^^^^^^^^^^^^^^^^^^
  File "/home/user/dev/mcp-server/.venv/lib/python3.12/site-packages/httpcore/_async/connection_pool.py", line 256, in handle_async_request
    raise exc from None
  File "/home/user/dev/mcp-server/.venv/lib/python3.12/site-packages/httpcore/_async/connection_pool.py", line 236, in handle_async_request
    response = await connection.handle_async_request(
               ^^^^^^^^^^^^^^^^^^^^^^^^^^^^^^^^^^^^^^
  File "/home/user/dev/mcp-server/.venv/lib/python3.12/site-packages/httpcore/_async/connection.py", line 103, in handle_async_request
    return await self._connection.handle_async_request(request)
           ^^^^^^^^^^^^^^^^^^^^^^^^^^^^^^^^^^^^^^^^^^^^^^^^^^^^
  File "/home/user/dev/mcp-server/.venv/lib/python3.12/site-packages/httpcore/_async/http11.py", line 136, in handle_async_request
    raise exc
  File "/home/user/dev/mcp-server/.venv/lib/python3.12/site-packages/httpcore/_async/http11.py", line 106, in handle_async_request
    ) = await self._receive_response_headers(**kwargs)
        ^^^^^^^^^^^^^^^^^^^^^^^^^^^^^^^^^^^^^^^^^^^^^^
  File "/home/user/dev/mcp-server/.venv/lib/python3.12/site-packages/httpcore/_async/http11.py", line 177, in _receive_response_headers
    event = await self._receive_event(timeout=timeout)
            ^^^^^^^^^^^^^^^^^^^^^^^^^^^^^^^^^^^^^^^^^^
  File "/home/user/dev/mcp-server/.venv/lib/python3.12/site-packages/httpcore/_async/http11.py", line 217, in _receive_event
    data = await self._network_stream.read(
           ^^^^^^^^^^^^^^^^^^^^^^^^^^^^^^^^
  File "/home/user/dev/mcp-server/.venv/lib/python3.12/site-packages/httpcore/_backends/anyio.py", line 32, in read
    with map_exceptions(exc_map):
  File "/usr/lib/python3.12/contextlib.py", line 158, in __exit__
    self.gen.throw(value)
  File "/home/user/dev/mcp-server/.venv/lib/python3.12/site-packages/httpcore/_exceptions.py", line 14, in map_exceptions
    raise to_exc(exc) from exc
httpcore.ReadTimeout

The above exception was the direct cause of the following exception:

Traceback (most recent call last):
  File "/home/user/dev/mcp-server/app/services/http_client.py", line 94, in _retry_request
    response = await client.request(method, url, **kwargs)
               ^^^^^^^^^^^^^^^^^^^^^^^^^^^^^^^^^^^^^^^^^^^
  File "/home/user/dev/mcp-server/.venv/lib/python3.12/site-packages/httpx/_client.py", line 1540, in request
    return await self.send(request, auth=auth, follow_redirects=follow_redirects)
           ^^^^^^^^^^^^^^^^^^^^^^^^^^^^^^^^^^^^^^^^^^^^^^^^^^^^^^^^^^^^^^^^^^^^^^
  File "/home/user/dev/mcp-server/.venv/lib/python3.12/site-packages/httpx/_client.py", line 1629, in send
    response = await self._send_handling_auth(
               ^^^^^^^^^^^^^^^^^^^^^^^^^^^^^^^
  File "/home/user/dev/mcp-server/.venv/lib/python3.12/site-packages/httpx/_client.py", line 1657, in _send_handling_auth
    response = await self._send_handling_redirects(
               ^^^^^^^^^^^^^^^^^^^^^^^^^^^^^^^^^^^^
  File "/home/user/dev/mcp-server/.venv/lib/python3.12/site-packages/httpx/_client.py", line 1694, in _send_handling_redirects
    response = await self._send_single_request(request)
               ^^^^^^^^^^^^^^^^^^^^^^^^^^^^^^^^^^^^^^^^
  File "/home/user/dev/mcp-server/.venv/lib/python3.12/site-packages/httpx/_client.py", line 1730, in _send_single_request
    response = await transport.handle_async_request(request)
               ^^^^^^^^^^^^^^^^^^^^^^^^^^^^^^^^^^^^^^^^^^^^^
  File "/home/user/dev/mcp-server/.venv/lib/python3.12/site-packages/httpx/_transports/default.py", line 393, in handle_async_request
    with map_httpcore_exceptions():
  File "/usr/lib/python3.12/contextlib.py", line 158, in __exit__
    self.gen.throw(value)
  File "/home/user/dev/mcp-server/.venv/lib/python3.12/site-packages/httpx/_transports/default.py", line 118, in map_httpcore_exceptions
    raise mapped_exc(message) from exc
httpx.ReadTimeout

During handling of the above exception, another exception occurred:

Traceback (most recent call last):
  File "/home/user/dev/mcp-server/app/services/fetch_data.py", line 60, in fetch_from_infosphere
    resp = await client.request(
           ^^^^^^^^^^^^^^^^^^^^^
  File "/home/user/dev/mcp-server/app/services/http_client.py", line 194, in request
    return await self._retry_request(method=method, url=url, **kwargs)
           ^^^^^^^^^^^^^^^^^^^^^^^^^^^^^^^^^^^^^^^^^^^^^^^^^^^^^^^^^^^
  File "/home/user/dev/mcp-server/app/services/http_client.py", line 115, in _retry_request
    logger.warning("Request error: %s. Retrying in %.2f seconds...", str(exc), delay)
TypeError: AppLogger.warning() takes from 2 to 3 positional arguments but 4 were given
[17:38:47] DEBUG | mcp-server | [CACHE] Skip caching error response: {'error': 'InfoSphere request failed: AppLogger.warning() takes from 2 to 3 positional arguments but 4 were given'}
[17:40:52] INFO | mcp-server | [TARANTOOL] Tarantool connection closed
[17:53:06] INFO | mcp-server | [TARANTOOL] Tarantool connected successfully
[17:53:10] ERROR | mcp-server | [APP] Error in process_prompt: 'SystemMessage' object has no attribute 'get'
Traceback (most recent call last):
  File "/home/user/dev/mcp-server/app/routes/agent_routes.py", line 46, in process_prompt
    final_state = await app_graph.ainvoke(initial_state)
                  ^^^^^^^^^^^^^^^^^^^^^^^^^^^^^^^^^^^^^^
  File "/home/user/dev/mcp-server/.venv/lib/python3.12/site-packages/langgraph/pregel/main.py", line 3112, in ainvoke
    async for chunk in self.astream(
  File "/home/user/dev/mcp-server/.venv/lib/python3.12/site-packages/langgraph/pregel/main.py", line 2939, in astream
    async for _ in runner.atick(
  File "/home/user/dev/mcp-server/.venv/lib/python3.12/site-packages/langgraph/pregel/_runner.py", line 295, in atick
    await arun_with_retry(
  File "/home/user/dev/mcp-server/.venv/lib/python3.12/site-packages/langgraph/pregel/_retry.py", line 137, in arun_with_retry
    return await task.proc.ainvoke(task.input, config)
           ^^^^^^^^^^^^^^^^^^^^^^^^^^^^^^^^^^^^^^^^^^^
  File "/home/user/dev/mcp-server/.venv/lib/python3.12/site-packages/langgraph/_internal/_runnable.py", line 706, in ainvoke
    input = await asyncio.create_task(
            ^^^^^^^^^^^^^^^^^^^^^^^^^^
  File "/home/user/dev/mcp-server/.venv/lib/python3.12/site-packages/langgraph/_internal/_runnable.py", line 474, in ainvoke
    ret = await self.afunc(*args, **kwargs)
          ^^^^^^^^^^^^^^^^^^^^^^^^^^^^^^^^^
  File "/home/user/dev/mcp-server/app/agent/server.py", line 144, in agent_node
    if not messages or messages[0].get("role") != "system":
                       ^^^^^^^^^^^^^^^
  File "/home/user/dev/mcp-server/.venv/lib/python3.12/site-packages/pydantic/main.py", line 991, in __getattr__
    raise AttributeError(f'{type(self).__name__!r} object has no attribute {item!r}')
AttributeError: 'SystemMessage' object has no attribute 'get'
During task with name 'agent' and id '42e2a44e-6f98-e209-682e-7c070de07eb7'
[17:53:47] INFO | mcp-server | [TARANTOOL] Tarantool connection closed
[17:53:51] INFO | mcp-server | [TARANTOOL] Tarantool connected successfully
[17:53:56] INFO | mcp-server | [COMPANY_INFO] Fetching data for INN: 6165231522
[17:53:56] ERROR | mcp-server | [TARANTOOL] Unexpected error on GET cache:18ff4cb6c031705995c5866e42ff0fb9: 3 exceeds max_map_len(2)
[17:53:56] ERROR | mcp-server | [TARANTOOL] Unexpected error on GET cache:18ff4cb6c031705995c5866e42ff0fb9: 3 exceeds max_map_len(2)
[17:53:56] ERROR | mcp-server | [TARANTOOL] Unexpected error on GET cache:b35111377fd6f940ce1cb56b9fcbc3f5: 3 exceeds max_map_len(2)
[17:53:56] ERROR | mcp-server | [TARANTOOL] Unexpected error on GET cache:3c5353609bd74cf49101cf9ff5d2460b: 'int' object has no attribute 'get'
[17:53:56] DEBUG | mcp-server | [CACHE] Cache MISS: app.services.fetch_data:fetch_from_dadata:6165231522 → cache:18ff4cb6c031705995c5866e42ff0fb9
[17:53:56] INFO | mcp-server | 
[17:53:56] DEBUG | mcp-server | [CACHE] Cache MISS: app.services.fetch_data:fetch_from_casebook:6165231522 → cache:b35111377fd6f940ce1cb56b9fcbc3f5
[17:53:56] INFO | mcp-server | 
[17:53:56] DEBUG | mcp-server | [CACHE] Cache MISS: app.services.fetch_data:fetch_from_infosphere:6165231522 → cache:3c5353609bd74cf49101cf9ff5d2460b
[17:53:56] INFO | mcp-server | 
[17:53:57] INFO | mcp-server | 
[17:53:57] ERROR | mcp-server | [HTTP_CLIENT] Ошибка при запросе страницы 1: 'int' object has no attribute 'upper'
[17:53:57] INFO | mcp-server | 
[17:53:57] DEBUG | mcp-server | [TARANTOOL] Cache set: cache:b35111377fd6f940ce1cb56b9fcbc3f5, ttl=9600
[17:53:57] DEBUG | mcp-server | [CACHE] Cache SET: cache:b35111377fd6f940ce1cb56b9fcbc3f5, ttl=9600
[17:53:57] DEBUG | mcp-server | [TARANTOOL] Cache set: cache:18ff4cb6c031705995c5866e42ff0fb9, ttl=7200
[17:53:57] DEBUG | mcp-server | [CACHE] Cache SET: cache:18ff4cb6c031705995c5866e42ff0fb9, ttl=7200
[17:54:01] INFO | mcp-server | 
[17:54:01] DEBUG | mcp-server | [TARANTOOL] Cache set: cache:3c5353609bd74cf49101cf9ff5d2460b, ttl=3600
[17:54:01] DEBUG | mcp-server | [CACHE] Cache SET: cache:3c5353609bd74cf49101cf9ff5d2460b, ttl=3600
[17:54:11] INFO | mcp-server | [APP] Session session_2686f6253e7a4832888fb439100d2fcc: completed prompt processing
[17:55:09] INFO | mcp-server | [TARANTOOL] Tarantool connection closed
[18:00:41] INFO | mcp-server | [TARANTOOL] Tarantool connected successfully
[18:00:47] INFO | mcp-server | [COMPANY_INFO] Fetching data for INN: 6165231522
[18:00:47] ERROR | mcp-server | [TARANTOOL] Unexpected error on GET cache:18ff4cb6c031705995c5866e42ff0fb9: 3 exceeds max_map_len(2)
[18:00:47] ERROR | mcp-server | [TARANTOOL] Unexpected error on GET cache:18ff4cb6c031705995c5866e42ff0fb9: 3 exceeds max_map_len(2)
[18:00:47] ERROR | mcp-server | [TARANTOOL] Unexpected error on GET cache:3c5353609bd74cf49101cf9ff5d2460b: 'int' object has no attribute 'get'
[18:00:47] ERROR | mcp-server | [TARANTOOL] Unexpected error on GET cache:3c5353609bd74cf49101cf9ff5d2460b: 'int' object has no attribute 'get'
[18:00:47] DEBUG | mcp-server | [CACHE] Cache MISS: app.services.fetch_data:fetch_from_dadata:6165231522 → cache:18ff4cb6c031705995c5866e42ff0fb9
[18:00:47] INFO | mcp-server | 
[18:00:47] DEBUG | mcp-server | [CACHE] Cache MISS: app.services.fetch_data:fetch_from_infosphere:6165231522 → cache:3c5353609bd74cf49101cf9ff5d2460b
[18:00:47] INFO | mcp-server | 
[18:00:47] DEBUG | mcp-server | [CACHE] Cache HIT: app.services.fetch_data:fetch_from_casebook:6165231522 → cache:b35111377fd6f940ce1cb56b9fcbc3f5
[18:00:47] INFO | mcp-server | 
[18:00:47] DEBUG | mcp-server | [TARANTOOL] Cache set: cache:18ff4cb6c031705995c5866e42ff0fb9, ttl=7200
[18:00:48] DEBUG | mcp-server | [CACHE] Cache SET: cache:18ff4cb6c031705995c5866e42ff0fb9, ttl=7200
[18:00:50] INFO | mcp-server | 
[18:00:50] DEBUG | mcp-server | [TARANTOOL] Cache set: cache:3c5353609bd74cf49101cf9ff5d2460b, ttl=3600
[18:00:50] DEBUG | mcp-server | [CACHE] Cache SET: cache:3c5353609bd74cf49101cf9ff5d2460b, ttl=3600
[18:00:59] INFO | mcp-server | [APP] Session session_047ca09fdea04c19b8a126013f24ebd9: completed prompt processing
[18:07:52] INFO | mcp-server | [APP] Session session_1ae121f4613b43e8a0c2e46d80ec6ece: completed prompt processing
[18:10:08] INFO | mcp-server | [TARANTOOL] Tarantool connection closed
[18:11:23] INFO | mcp-server | [TARANTOOL] Tarantool connected successfully
[18:11:32] INFO | mcp-server | [COMPANY_INFO] Fetching data for INN: 6165231522
[18:11:32] DEBUG | mcp-server | [CACHE] Cache HIT: app.services.fetch_data:fetch_from_infosphere:6165231522 → cache:3c5353609bd74cf49101cf9ff5d2460b
[18:11:32] DEBUG | mcp-server | [CACHE] Cache HIT: app.services.fetch_data:fetch_from_dadata:6165231522 → cache:18ff4cb6c031705995c5866e42ff0fb9
[18:11:32] DEBUG | mcp-server | [CACHE] Cache HIT: app.services.fetch_data:fetch_from_casebook:6165231522 → cache:b35111377fd6f940ce1cb56b9fcbc3f5
[18:11:49] INFO | mcp-server | [APP] Session session_2f413ffabe7f4c1286d07a67af9d57d1: completed prompt processing
[18:15:53] INFO | mcp-server | [TARANTOOL] Tarantool connection closed
[18:16:39] INFO | mcp-server | [TARANTOOL] Tarantool connected successfully
[18:16:55] INFO | mcp-server | [COMPANY_INFO] Fetching data for INN: 6165231522
[18:16:55] DEBUG | mcp-server | [CACHE] Cache HIT: app.services.fetch_data:fetch_from_infosphere:6165231522 → cache:3c5353609bd74cf49101cf9ff5d2460b
[18:16:55] DEBUG | mcp-server | [CACHE] Cache HIT: app.services.fetch_data:fetch_from_dadata:6165231522 → cache:18ff4cb6c031705995c5866e42ff0fb9
[18:16:55] DEBUG | mcp-server | [CACHE] Cache HIT: app.services.fetch_data:fetch_from_casebook:6165231522 → cache:b35111377fd6f940ce1cb56b9fcbc3f5
[18:17:03] INFO | mcp-server | [APP] Session session_6767ee2a73dc4ae2b11436ccaead77de: completed prompt processing
[18:17:22] INFO | mcp-server | [TARANTOOL] Tarantool connection closed
